Traceback (most recent call last):
  File "/nix/store/sy4nw98mprmxcf8xpqzqm227ghhvaakq-nix-update-1.5.2/bin/.nix-update-wrapped", line 9, in <module>
    sys.exit(main())
             ^^^^^^
  File "/nix/store/sy4nw98mprmxcf8xpqzqm227ghhvaakq-nix-update-1.5.2/lib/python3.12/site-packages/nix_update/__init__.py", line 311, in main
    package = update(options)
              ^^^^^^^^^^^^^^^
  File "/nix/store/sy4nw98mprmxcf8xpqzqm227ghhvaakq-nix-update-1.5.2/lib/python3.12/site-packages/nix_update/update.py", line 449, in update
    update_hash = update_version(
                  ^^^^^^^^^^^^^^^
  File "/nix/store/sy4nw98mprmxcf8xpqzqm227ghhvaakq-nix-update-1.5.2/lib/python3.12/site-packages/nix_update/update.py", line 383, in update_version
    new_version = fetch_latest_version(
                  ^^^^^^^^^^^^^^^^^^^^^
  File "/nix/store/sy4nw98mprmxcf8xpqzqm227ghhvaakq-nix-update-1.5.2/lib/python3.12/site-packages/nix_update/version/__init__.py", line 93, in fetch_latest_version
    versions = fetcher(url)
               ^^^^^^^^^^^^
  File "/nix/store/sy4nw98mprmxcf8xpqzqm227ghhvaakq-nix-update-1.5.2/lib/python3.12/site-packages/nix_update/version/github.py", line 32, in fetch_github_versions
    resp = urllib.request.urlopen(feed_url)
           ^^^^^^^^^^^^^^^^^^^^^^^^^^^^^^^^
  File "/nix/store/h3i0acpmr8mrjx07519xxmidv8mpax4y-python3-3.12.5/lib/python3.12/urllib/request.py", line 215, in urlopen
    return opener.open(url, data, timeout)
           ^^^^^^^^^^^^^^^^^^^^^^^^^^^^^^^
  File "/nix/store/h3i0acpmr8mrjx07519xxmidv8mpax4y-python3-3.12.5/lib/python3.12/urllib/request.py", line 521, in open
    response = meth(req, response)
               ^^^^^^^^^^^^^^^^^^^
  File "/nix/store/h3i0acpmr8mrjx07519xxmidv8mpax4y-python3-3.12.5/lib/python3.12/urllib/request.py", line 630, in http_response
    response = self.parent.error(
               ^^^^^^^^^^^^^^^^^^
  File "/nix/store/h3i0acpmr8mrjx07519xxmidv8mpax4y-python3-3.12.5/lib/python3.12/urllib/request.py", line 559, in error
    return self._call_chain(*args)
           ^^^^^^^^^^^^^^^^^^^^^^^
  File "/nix/store/h3i0acpmr8mrjx07519xxmidv8mpax4y-python3-3.12.5/lib/python3.12/urllib/request.py", line 492, in _call_chain
    result = func(*args)
             ^^^^^^^^^^^
  File "/nix/store/h3i0acpmr8mrjx07519xxmidv8mpax4y-python3-3.12.5/lib/python3.12/urllib/request.py", line 639, in http_error_default
    raise HTTPError(req.full_url, code, msg, hdrs, fp)
urllib.error.HTTPError: HTTP Error 404: Not Found
